[2025-01-17T11:46:04.383+0000] {local_task_job_runner.py:123} INFO - ::group::Pre task execution logs
[2025-01-17T11:46:04.619+0000] {taskinstance.py:2613} INFO - Dependencies all met for dep_context=non-requeueable deps ti=<TaskInstance: user_data_to_duckdb.run_dbt_transform manual__2025-01-17T11:25:03.967012+00:00 [queued]>
[2025-01-17T11:46:04.642+0000] {taskinstance.py:2613} INFO - Dependencies all met for dep_context=requeueable deps ti=<TaskInstance: user_data_to_duckdb.run_dbt_transform manual__2025-01-17T11:25:03.967012+00:00 [queued]>
[2025-01-17T11:46:04.643+0000] {taskinstance.py:2866} INFO - Starting attempt 1 of 2
[2025-01-17T11:46:04.675+0000] {taskinstance.py:2889} INFO - Executing <Task(BashOperator): run_dbt_transform> on 2025-01-17 11:25:03.967012+00:00
[2025-01-17T11:46:04.689+0000] {warnings.py:112} WARNING - /home/***/.local/lib/python3.12/site-packages/***/task/task_runner/standard_task_runner.py:70: DeprecationWarning: This process (pid=294) is multi-threaded, use of fork() may lead to deadlocks in the child.
  pid = os.fork()

[2025-01-17T11:46:04.693+0000] {standard_task_runner.py:72} INFO - Started process 299 to run task
[2025-01-17T11:46:04.694+0000] {standard_task_runner.py:104} INFO - Running: ['***', 'tasks', 'run', 'user_data_to_duckdb', 'run_dbt_transform', 'manual__2025-01-17T11:25:03.967012+00:00', '--job-id', '105', '--raw', '--subdir', 'DAGS_FOLDER/api_duckdb_dag.py', '--cfg-path', '/tmp/tmp08v07iyt']
[2025-01-17T11:46:04.728+0000] {standard_task_runner.py:105} INFO - Job 105: Subtask run_dbt_transform
[2025-01-17T11:46:04.888+0000] {task_command.py:467} INFO - Running <TaskInstance: user_data_to_duckdb.run_dbt_transform manual__2025-01-17T11:25:03.967012+00:00 [running]> on host 78d3b8284409
[2025-01-17T11:46:05.146+0000] {taskinstance.py:3132} INFO - Exporting env vars: AIRFLOW_CTX_DAG_OWNER='***' AIRFLOW_CTX_DAG_ID='user_data_to_duckdb' AIRFLOW_CTX_TASK_ID='run_dbt_transform' AIRFLOW_CTX_EXECUTION_DATE='2025-01-17T11:25:03.967012+00:00' AIRFLOW_CTX_TRY_NUMBER='1' AIRFLOW_CTX_DAG_RUN_ID='manual__2025-01-17T11:25:03.967012+00:00'
[2025-01-17T11:46:05.149+0000] {logging_mixin.py:190} INFO - Task instance is in running state
[2025-01-17T11:46:05.151+0000] {logging_mixin.py:190} INFO -  Previous state of the Task instance: queued
[2025-01-17T11:46:05.152+0000] {logging_mixin.py:190} INFO - Current task name:run_dbt_transform state:running start_date:2025-01-17 11:46:04.620934+00:00
[2025-01-17T11:46:05.152+0000] {logging_mixin.py:190} INFO - Dag name:user_data_to_duckdb and current dag run status:running
[2025-01-17T11:46:05.153+0000] {taskinstance.py:731} INFO - ::endgroup::
[2025-01-17T11:46:05.160+0000] {subprocess.py:78} INFO - Tmp dir root location: /tmp
[2025-01-17T11:46:05.162+0000] {subprocess.py:88} INFO - Running command: ['/usr/bin/bash', '-c', '\n        cd /opt/***/dags/dbt_models &&         dbt run --profiles-dir /opt/***/.dbt --target dev\n        ']
[2025-01-17T11:46:05.185+0000] {subprocess.py:99} INFO - Output:
[2025-01-17T11:46:12.213+0000] {subprocess.py:106} INFO - [0m11:46:12  Running with dbt=1.9.1
[2025-01-17T11:46:12.220+0000] {subprocess.py:106} INFO - [0m11:46:12  Encountered an error:
[2025-01-17T11:46:12.221+0000] {subprocess.py:106} INFO - Runtime Error
[2025-01-17T11:46:12.223+0000] {subprocess.py:106} INFO -   No dbt_project.yml found at expected path /opt/***/dags/dbt_models/dbt_project.yml
[2025-01-17T11:46:12.225+0000] {subprocess.py:106} INFO -   Verify that each entry within packages.yml (and their transitive dependencies) contains a file named dbt_project.yml
[2025-01-17T11:46:12.227+0000] {subprocess.py:106} INFO - 
[2025-01-17T11:46:12.762+0000] {subprocess.py:110} INFO - Command exited with return code 2
[2025-01-17T11:46:12.792+0000] {taskinstance.py:3311} ERROR - Task failed with exception
Traceback (most recent call last):
  File "/home/airflow/.local/lib/python3.12/site-packages/airflow/models/taskinstance.py", line 767, in _execute_task
    result = _execute_callable(context=context, **execute_callable_kwargs)
             ^^^^^^^^^^^^^^^^^^^^^^^^^^^^^^^^^^^^^^^^^^^^^^^^^^^^^^^^^^^^^
  File "/home/airflow/.local/lib/python3.12/site-packages/airflow/models/taskinstance.py", line 733, in _execute_callable
    return ExecutionCallableRunner(
           ^^^^^^^^^^^^^^^^^^^^^^^^
  File "/home/airflow/.local/lib/python3.12/site-packages/airflow/utils/operator_helpers.py", line 252, in run
    return self.func(*args, **kwargs)
           ^^^^^^^^^^^^^^^^^^^^^^^^^^
  File "/home/airflow/.local/lib/python3.12/site-packages/airflow/models/baseoperator.py", line 422, in wrapper
    return func(self, *args, **kwargs)
           ^^^^^^^^^^^^^^^^^^^^^^^^^^^
  File "/home/airflow/.local/lib/python3.12/site-packages/airflow/operators/bash.py", line 276, in execute
    raise AirflowException(
airflow.exceptions.AirflowException: Bash command failed. The command returned a non-zero exit code 2.
[2025-01-17T11:46:12.823+0000] {logging_mixin.py:190} INFO - Task instance in failure state
[2025-01-17T11:46:12.824+0000] {logging_mixin.py:190} INFO - Task start:2025-01-17 11:46:04.620934+00:00 end:2025-01-17 11:46:12.821951+00:00 duration:8.201017
[2025-01-17T11:46:12.825+0000] {logging_mixin.py:190} INFO - Task:<Task(BashOperator): run_dbt_transform> dag:<DAG: user_data_to_duckdb> dagrun:<DagRun user_data_to_duckdb @ 2025-01-17 11:25:03.967012+00:00: manual__2025-01-17T11:25:03.967012+00:00, state:running, queued_at: 2025-01-17 11:25:04.015306+00:00. externally triggered: True>
[2025-01-17T11:46:12.826+0000] {logging_mixin.py:190} INFO - Failure caused by Bash command failed. The command returned a non-zero exit code 2.
[2025-01-17T11:46:12.828+0000] {taskinstance.py:1225} INFO - Marking task as UP_FOR_RETRY. dag_id=user_data_to_duckdb, task_id=run_dbt_transform, run_id=manual__2025-01-17T11:25:03.967012+00:00, execution_date=20250117T112503, start_date=20250117T114604, end_date=20250117T114612
[2025-01-17T11:46:12.868+0000] {taskinstance.py:340} INFO - ::group::Post task execution logs
[2025-01-17T11:46:12.871+0000] {standard_task_runner.py:124} ERROR - Failed to execute job 105 for task run_dbt_transform (Bash command failed. The command returned a non-zero exit code 2.; 299)
Traceback (most recent call last):
  File "/home/airflow/.local/lib/python3.12/site-packages/airflow/task/task_runner/standard_task_runner.py", line 117, in _start_by_fork
    ret = args.func(args, dag=self.dag)
          ^^^^^^^^^^^^^^^^^^^^^^^^^^^^^
  File "/home/airflow/.local/lib/python3.12/site-packages/airflow/cli/cli_config.py", line 49, in command
    return func(*args, **kwargs)
           ^^^^^^^^^^^^^^^^^^^^^
  File "/home/airflow/.local/lib/python3.12/site-packages/airflow/utils/cli.py", line 116, in wrapper
    return f(*args, **kwargs)
           ^^^^^^^^^^^^^^^^^^
  File "/home/airflow/.local/lib/python3.12/site-packages/airflow/cli/commands/task_command.py", line 483, in task_run
    task_return_code = _run_task_by_selected_method(args, _dag, ti)
                       ^^^^^^^^^^^^^^^^^^^^^^^^^^^^^^^^^^^^^^^^^^^^
  File "/home/airflow/.local/lib/python3.12/site-packages/airflow/cli/commands/task_command.py", line 256, in _run_task_by_selected_method
    return _run_raw_task(args, ti)
           ^^^^^^^^^^^^^^^^^^^^^^^
  File "/home/airflow/.local/lib/python3.12/site-packages/airflow/cli/commands/task_command.py", line 341, in _run_raw_task
    return ti._run_raw_task(
           ^^^^^^^^^^^^^^^^^
  File "/home/airflow/.local/lib/python3.12/site-packages/airflow/utils/session.py", line 97, in wrapper
    return func(*args, session=session, **kwargs)
           ^^^^^^^^^^^^^^^^^^^^^^^^^^^^^^^^^^^^^^
  File "/home/airflow/.local/lib/python3.12/site-packages/airflow/models/taskinstance.py", line 3005, in _run_raw_task
    return _run_raw_task(
           ^^^^^^^^^^^^^^
  File "/home/airflow/.local/lib/python3.12/site-packages/airflow/models/taskinstance.py", line 273, in _run_raw_task
    TaskInstance._execute_task_with_callbacks(
  File "/home/airflow/.local/lib/python3.12/site-packages/airflow/models/taskinstance.py", line 3159, in _execute_task_with_callbacks
    result = self._execute_task(context, task_orig)
             ^^^^^^^^^^^^^^^^^^^^^^^^^^^^^^^^^^^^^^
  File "/home/airflow/.local/lib/python3.12/site-packages/airflow/models/taskinstance.py", line 3183, in _execute_task
    return _execute_task(self, context, task_orig)
           ^^^^^^^^^^^^^^^^^^^^^^^^^^^^^^^^^^^^^^^
  File "/home/airflow/.local/lib/python3.12/site-packages/airflow/models/taskinstance.py", line 767, in _execute_task
    result = _execute_callable(context=context, **execute_callable_kwargs)
             ^^^^^^^^^^^^^^^^^^^^^^^^^^^^^^^^^^^^^^^^^^^^^^^^^^^^^^^^^^^^^
  File "/home/airflow/.local/lib/python3.12/site-packages/airflow/models/taskinstance.py", line 733, in _execute_callable
    return ExecutionCallableRunner(
           ^^^^^^^^^^^^^^^^^^^^^^^^
  File "/home/airflow/.local/lib/python3.12/site-packages/airflow/utils/operator_helpers.py", line 252, in run
    return self.func(*args, **kwargs)
           ^^^^^^^^^^^^^^^^^^^^^^^^^^
  File "/home/airflow/.local/lib/python3.12/site-packages/airflow/models/baseoperator.py", line 422, in wrapper
    return func(self, *args, **kwargs)
           ^^^^^^^^^^^^^^^^^^^^^^^^^^^
  File "/home/airflow/.local/lib/python3.12/site-packages/airflow/operators/bash.py", line 276, in execute
    raise AirflowException(
airflow.exceptions.AirflowException: Bash command failed. The command returned a non-zero exit code 2.
[2025-01-17T11:46:12.945+0000] {local_task_job_runner.py:266} INFO - Task exited with return code 1
[2025-01-17T11:46:13.010+0000] {taskinstance.py:3895} INFO - 0 downstream tasks scheduled from follow-on schedule check
[2025-01-17T11:46:13.014+0000] {local_task_job_runner.py:245} INFO - ::endgroup::
