[2025-01-20T08:19:45.594+0000] {local_task_job_runner.py:123} INFO - ::group::Pre task execution logs
[2025-01-20T08:19:45.780+0000] {taskinstance.py:2613} INFO - Dependencies all met for dep_context=non-requeueable deps ti=<TaskInstance: user_data_to_duckdb.run_dbt_transform scheduled__2025-01-19T00:00:00+00:00 [queued]>
[2025-01-20T08:19:45.797+0000] {taskinstance.py:2613} INFO - Dependencies all met for dep_context=requeueable deps ti=<TaskInstance: user_data_to_duckdb.run_dbt_transform scheduled__2025-01-19T00:00:00+00:00 [queued]>
[2025-01-20T08:19:45.799+0000] {taskinstance.py:2866} INFO - Starting attempt 3 of 3
[2025-01-20T08:19:45.825+0000] {taskinstance.py:2889} INFO - Executing <Task(BashOperator): run_dbt_transform> on 2025-01-19 00:00:00+00:00
[2025-01-20T08:19:45.839+0000] {warnings.py:112} WARNING - /home/***/.local/lib/python3.12/site-packages/***/task/task_runner/standard_task_runner.py:70: DeprecationWarning: This process (pid=368) is multi-threaded, use of fork() may lead to deadlocks in the child.
  pid = os.fork()

[2025-01-20T08:19:45.841+0000] {standard_task_runner.py:72} INFO - Started process 373 to run task
[2025-01-20T08:19:45.842+0000] {standard_task_runner.py:104} INFO - Running: ['***', 'tasks', 'run', 'user_data_to_duckdb', 'run_dbt_transform', 'scheduled__2025-01-19T00:00:00+00:00', '--job-id', '14', '--raw', '--subdir', 'DAGS_FOLDER/api_duckdb_dag.py', '--cfg-path', '/tmp/tmp9dbkx_xg']
[2025-01-20T08:19:45.844+0000] {standard_task_runner.py:105} INFO - Job 14: Subtask run_dbt_transform
[2025-01-20T08:19:45.923+0000] {task_command.py:467} INFO - Running <TaskInstance: user_data_to_duckdb.run_dbt_transform scheduled__2025-01-19T00:00:00+00:00 [running]> on host af5c9462b200
[2025-01-20T08:19:46.059+0000] {taskinstance.py:3132} INFO - Exporting env vars: AIRFLOW_CTX_DAG_OWNER='***' AIRFLOW_CTX_DAG_ID='user_data_to_duckdb' AIRFLOW_CTX_TASK_ID='run_dbt_transform' AIRFLOW_CTX_EXECUTION_DATE='2025-01-19T00:00:00+00:00' AIRFLOW_CTX_TRY_NUMBER='3' AIRFLOW_CTX_DAG_RUN_ID='scheduled__2025-01-19T00:00:00+00:00'
[2025-01-20T08:19:46.062+0000] {logging_mixin.py:190} INFO - Task instance is in running state
[2025-01-20T08:19:46.062+0000] {logging_mixin.py:190} INFO -  Previous state of the Task instance: queued
[2025-01-20T08:19:46.063+0000] {logging_mixin.py:190} INFO - Current task name:run_dbt_transform state:running start_date:2025-01-20 08:19:45.781111+00:00
[2025-01-20T08:19:46.064+0000] {logging_mixin.py:190} INFO - Dag name:user_data_to_duckdb and current dag run status:running
[2025-01-20T08:19:46.065+0000] {taskinstance.py:731} INFO - ::endgroup::
[2025-01-20T08:19:46.067+0000] {subprocess.py:78} INFO - Tmp dir root location: /tmp
[2025-01-20T08:19:46.070+0000] {subprocess.py:88} INFO - Running command: ['/usr/bin/bash', '-c', '\n        cd /opt/***/dags/dbt_models &&         dbt run --profiles-dir /opt/***/dbt/profiles.yml --target dev\n        ']
[2025-01-20T08:19:46.090+0000] {subprocess.py:99} INFO - Output:
[2025-01-20T08:19:51.454+0000] {subprocess.py:106} INFO - [0m08:19:51  Running with dbt=1.9.1
[2025-01-20T08:19:52.368+0000] {subprocess.py:106} INFO - [0m08:19:52  Registered adapter: duckdb=1.9.1
[2025-01-20T08:19:52.690+0000] {subprocess.py:106} INFO - [0m08:19:52  Unable to do partial parsing because a project config has changed
[2025-01-20T08:19:55.544+0000] {subprocess.py:106} INFO - [0m08:19:55  Encountered an error:
[2025-01-20T08:19:55.546+0000] {subprocess.py:106} INFO - Compilation Error
[2025-01-20T08:19:55.547+0000] {subprocess.py:106} INFO -   Model 'model.my_dbt_project.transform_users' (models/transform_users.sql) depends on a source named 'my_dbt_profile.users' which was not found
[2025-01-20T08:19:57.250+0000] {subprocess.py:110} INFO - Command exited with return code 2
[2025-01-20T08:19:57.278+0000] {taskinstance.py:3311} ERROR - Task failed with exception
Traceback (most recent call last):
  File "/home/airflow/.local/lib/python3.12/site-packages/airflow/models/taskinstance.py", line 767, in _execute_task
    result = _execute_callable(context=context, **execute_callable_kwargs)
             ^^^^^^^^^^^^^^^^^^^^^^^^^^^^^^^^^^^^^^^^^^^^^^^^^^^^^^^^^^^^^
  File "/home/airflow/.local/lib/python3.12/site-packages/airflow/models/taskinstance.py", line 733, in _execute_callable
    return ExecutionCallableRunner(
           ^^^^^^^^^^^^^^^^^^^^^^^^
  File "/home/airflow/.local/lib/python3.12/site-packages/airflow/utils/operator_helpers.py", line 252, in run
    return self.func(*args, **kwargs)
           ^^^^^^^^^^^^^^^^^^^^^^^^^^
  File "/home/airflow/.local/lib/python3.12/site-packages/airflow/models/baseoperator.py", line 422, in wrapper
    return func(self, *args, **kwargs)
           ^^^^^^^^^^^^^^^^^^^^^^^^^^^
  File "/home/airflow/.local/lib/python3.12/site-packages/airflow/operators/bash.py", line 276, in execute
    raise AirflowException(
airflow.exceptions.AirflowException: Bash command failed. The command returned a non-zero exit code 2.
[2025-01-20T08:19:57.288+0000] {logging_mixin.py:190} INFO - Task instance in failure state
[2025-01-20T08:19:57.289+0000] {logging_mixin.py:190} INFO - Task start:2025-01-20 08:19:45.781111+00:00 end:2025-01-20 08:19:57.287212+00:00 duration:11.506101
[2025-01-20T08:19:57.290+0000] {logging_mixin.py:190} INFO - Task:<Task(BashOperator): run_dbt_transform> dag:<DAG: user_data_to_duckdb> dagrun:<DagRun user_data_to_duckdb @ 2025-01-19 00:00:00+00:00: scheduled__2025-01-19T00:00:00+00:00, state:running, queued_at: 2025-01-20 08:08:54.720969+00:00. externally triggered: False>
[2025-01-20T08:19:57.291+0000] {logging_mixin.py:190} INFO - Failure caused by Bash command failed. The command returned a non-zero exit code 2.
[2025-01-20T08:19:57.292+0000] {taskinstance.py:1225} INFO - Marking task as FAILED. dag_id=user_data_to_duckdb, task_id=run_dbt_transform, run_id=scheduled__2025-01-19T00:00:00+00:00, execution_date=20250119T000000, start_date=20250120T081945, end_date=20250120T081957
[2025-01-20T08:19:57.322+0000] {taskinstance.py:340} INFO - ::group::Post task execution logs
[2025-01-20T08:19:57.323+0000] {standard_task_runner.py:124} ERROR - Failed to execute job 14 for task run_dbt_transform (Bash command failed. The command returned a non-zero exit code 2.; 373)
Traceback (most recent call last):
  File "/home/airflow/.local/lib/python3.12/site-packages/airflow/task/task_runner/standard_task_runner.py", line 117, in _start_by_fork
    ret = args.func(args, dag=self.dag)
          ^^^^^^^^^^^^^^^^^^^^^^^^^^^^^
  File "/home/airflow/.local/lib/python3.12/site-packages/airflow/cli/cli_config.py", line 49, in command
    return func(*args, **kwargs)
           ^^^^^^^^^^^^^^^^^^^^^
  File "/home/airflow/.local/lib/python3.12/site-packages/airflow/utils/cli.py", line 116, in wrapper
    return f(*args, **kwargs)
           ^^^^^^^^^^^^^^^^^^
  File "/home/airflow/.local/lib/python3.12/site-packages/airflow/cli/commands/task_command.py", line 483, in task_run
    task_return_code = _run_task_by_selected_method(args, _dag, ti)
                       ^^^^^^^^^^^^^^^^^^^^^^^^^^^^^^^^^^^^^^^^^^^^
  File "/home/airflow/.local/lib/python3.12/site-packages/airflow/cli/commands/task_command.py", line 256, in _run_task_by_selected_method
    return _run_raw_task(args, ti)
           ^^^^^^^^^^^^^^^^^^^^^^^
  File "/home/airflow/.local/lib/python3.12/site-packages/airflow/cli/commands/task_command.py", line 341, in _run_raw_task
    return ti._run_raw_task(
           ^^^^^^^^^^^^^^^^^
  File "/home/airflow/.local/lib/python3.12/site-packages/airflow/utils/session.py", line 97, in wrapper
    return func(*args, session=session, **kwargs)
           ^^^^^^^^^^^^^^^^^^^^^^^^^^^^^^^^^^^^^^
  File "/home/airflow/.local/lib/python3.12/site-packages/airflow/models/taskinstance.py", line 3005, in _run_raw_task
    return _run_raw_task(
           ^^^^^^^^^^^^^^
  File "/home/airflow/.local/lib/python3.12/site-packages/airflow/models/taskinstance.py", line 273, in _run_raw_task
    TaskInstance._execute_task_with_callbacks(
  File "/home/airflow/.local/lib/python3.12/site-packages/airflow/models/taskinstance.py", line 3159, in _execute_task_with_callbacks
    result = self._execute_task(context, task_orig)
             ^^^^^^^^^^^^^^^^^^^^^^^^^^^^^^^^^^^^^^
  File "/home/airflow/.local/lib/python3.12/site-packages/airflow/models/taskinstance.py", line 3183, in _execute_task
    return _execute_task(self, context, task_orig)
           ^^^^^^^^^^^^^^^^^^^^^^^^^^^^^^^^^^^^^^^
  File "/home/airflow/.local/lib/python3.12/site-packages/airflow/models/taskinstance.py", line 767, in _execute_task
    result = _execute_callable(context=context, **execute_callable_kwargs)
             ^^^^^^^^^^^^^^^^^^^^^^^^^^^^^^^^^^^^^^^^^^^^^^^^^^^^^^^^^^^^^
  File "/home/airflow/.local/lib/python3.12/site-packages/airflow/models/taskinstance.py", line 733, in _execute_callable
    return ExecutionCallableRunner(
           ^^^^^^^^^^^^^^^^^^^^^^^^
  File "/home/airflow/.local/lib/python3.12/site-packages/airflow/utils/operator_helpers.py", line 252, in run
    return self.func(*args, **kwargs)
           ^^^^^^^^^^^^^^^^^^^^^^^^^^
  File "/home/airflow/.local/lib/python3.12/site-packages/airflow/models/baseoperator.py", line 422, in wrapper
    return func(self, *args, **kwargs)
           ^^^^^^^^^^^^^^^^^^^^^^^^^^^
  File "/home/airflow/.local/lib/python3.12/site-packages/airflow/operators/bash.py", line 276, in execute
    raise AirflowException(
airflow.exceptions.AirflowException: Bash command failed. The command returned a non-zero exit code 2.
[2025-01-20T08:19:57.396+0000] {local_task_job_runner.py:266} INFO - Task exited with return code 1
[2025-01-20T08:19:57.427+0000] {taskinstance.py:3895} INFO - 0 downstream tasks scheduled from follow-on schedule check
[2025-01-20T08:19:57.430+0000] {local_task_job_runner.py:245} INFO - ::endgroup::
