[2025-01-20T08:26:32.698+0000] {local_task_job_runner.py:123} INFO - ::group::Pre task execution logs
[2025-01-20T08:26:32.873+0000] {taskinstance.py:2613} INFO - Dependencies all met for dep_context=non-requeueable deps ti=<TaskInstance: user_data_to_duckdb.run_dbt_transform manual__2025-01-20T08:08:50.334185+00:00 [queued]>
[2025-01-20T08:26:32.887+0000] {taskinstance.py:2613} INFO - Dependencies all met for dep_context=requeueable deps ti=<TaskInstance: user_data_to_duckdb.run_dbt_transform manual__2025-01-20T08:08:50.334185+00:00 [queued]>
[2025-01-20T08:26:32.888+0000] {taskinstance.py:2866} INFO - Starting attempt 3 of 3
[2025-01-20T08:26:32.910+0000] {taskinstance.py:2889} INFO - Executing <Task(BashOperator): run_dbt_transform> on 2025-01-20 08:08:50.334185+00:00
[2025-01-20T08:26:32.922+0000] {warnings.py:112} WARNING - /home/***/.local/lib/python3.12/site-packages/***/task/task_runner/standard_task_runner.py:70: DeprecationWarning: This process (pid=480) is multi-threaded, use of fork() may lead to deadlocks in the child.
  pid = os.fork()

[2025-01-20T08:26:32.925+0000] {standard_task_runner.py:72} INFO - Started process 485 to run task
[2025-01-20T08:26:32.926+0000] {standard_task_runner.py:104} INFO - Running: ['***', 'tasks', 'run', 'user_data_to_duckdb', 'run_dbt_transform', 'manual__2025-01-20T08:08:50.334185+00:00', '--job-id', '18', '--raw', '--subdir', 'DAGS_FOLDER/api_duckdb_dag.py', '--cfg-path', '/tmp/tmph1pfs1r1']
[2025-01-20T08:26:32.928+0000] {standard_task_runner.py:105} INFO - Job 18: Subtask run_dbt_transform
[2025-01-20T08:26:33.005+0000] {task_command.py:467} INFO - Running <TaskInstance: user_data_to_duckdb.run_dbt_transform manual__2025-01-20T08:08:50.334185+00:00 [running]> on host af5c9462b200
[2025-01-20T08:26:33.121+0000] {taskinstance.py:3132} INFO - Exporting env vars: AIRFLOW_CTX_DAG_OWNER='***' AIRFLOW_CTX_DAG_ID='user_data_to_duckdb' AIRFLOW_CTX_TASK_ID='run_dbt_transform' AIRFLOW_CTX_EXECUTION_DATE='2025-01-20T08:08:50.334185+00:00' AIRFLOW_CTX_TRY_NUMBER='3' AIRFLOW_CTX_DAG_RUN_ID='manual__2025-01-20T08:08:50.334185+00:00'
[2025-01-20T08:26:33.123+0000] {logging_mixin.py:190} INFO - Task instance is in running state
[2025-01-20T08:26:33.124+0000] {logging_mixin.py:190} INFO -  Previous state of the Task instance: queued
[2025-01-20T08:26:33.125+0000] {logging_mixin.py:190} INFO - Current task name:run_dbt_transform state:running start_date:2025-01-20 08:26:32.874416+00:00
[2025-01-20T08:26:33.126+0000] {logging_mixin.py:190} INFO - Dag name:user_data_to_duckdb and current dag run status:running
[2025-01-20T08:26:33.127+0000] {taskinstance.py:731} INFO - ::endgroup::
[2025-01-20T08:26:33.129+0000] {subprocess.py:78} INFO - Tmp dir root location: /tmp
[2025-01-20T08:26:33.132+0000] {subprocess.py:88} INFO - Running command: ['/usr/bin/bash', '-c', '\n        cd /opt/***/dags/dbt_models &&         dbt run --profiles-dir /opt/***/dbt/profiles.yml --target dev\n        ']
[2025-01-20T08:26:33.152+0000] {subprocess.py:99} INFO - Output:
[2025-01-20T08:26:37.750+0000] {subprocess.py:106} INFO - [0m08:26:37  Running with dbt=1.9.1
[2025-01-20T08:26:38.424+0000] {subprocess.py:106} INFO - [0m08:26:38  Registered adapter: duckdb=1.9.1
[2025-01-20T08:26:38.747+0000] {subprocess.py:106} INFO - [0m08:26:38  Unable to do partial parsing because a project config has changed
[2025-01-20T08:26:44.734+0000] {subprocess.py:106} INFO - [0m08:26:44  Found 1 model, 1 source, 424 macros
[2025-01-20T08:26:44.757+0000] {subprocess.py:106} INFO - [0m08:26:44
[2025-01-20T08:26:44.780+0000] {subprocess.py:106} INFO - [0m08:26:44  Concurrency: 1 threads (target='dev')
[2025-01-20T08:26:44.800+0000] {subprocess.py:106} INFO - [0m08:26:44
[2025-01-20T08:27:16.451+0000] {subprocess.py:106} INFO - [0m08:27:16  1 of 1 START sql table model main.transform_users .............................. [RUN]
[2025-01-20T08:27:17.592+0000] {job.py:229} INFO - Heartbeat recovered after 34.19 seconds
[2025-01-20T08:27:18.839+0000] {subprocess.py:106} INFO - [0m08:27:18  1 of 1 ERROR creating sql table model main.transform_users ..................... [[31mERROR[0m in 2.36s]
[2025-01-20T08:27:19.480+0000] {subprocess.py:106} INFO - [0m08:27:19
[2025-01-20T08:27:19.505+0000] {subprocess.py:106} INFO - [0m08:27:19  Finished running 1 table model in 0 hours 0 minutes and 34.71 seconds (34.71s).
[2025-01-20T08:27:20.368+0000] {subprocess.py:106} INFO - [0m08:27:20
[2025-01-20T08:27:20.382+0000] {subprocess.py:106} INFO - [0m08:27:20  [31mCompleted with 1 error, 0 partial successes, and 0 warnings:[0m
[2025-01-20T08:27:20.389+0000] {subprocess.py:106} INFO - [0m08:27:20
[2025-01-20T08:27:20.417+0000] {subprocess.py:106} INFO - [0m08:27:20    Runtime Error in model transform_users (models/transform_users.sql)
[2025-01-20T08:27:20.423+0000] {subprocess.py:106} INFO -   Catalog Error: Table with name users does not exist!
[2025-01-20T08:27:20.436+0000] {subprocess.py:106} INFO -   Did you mean "my_duckdb_database.users"?
[2025-01-20T08:27:20.444+0000] {subprocess.py:106} INFO -   LINE 15:     SELECT * FROM "my_duckdb_database"."public"."users"
[2025-01-20T08:27:20.446+0000] {subprocess.py:106} INFO -                              ^
[2025-01-20T08:27:20.449+0000] {subprocess.py:106} INFO - [0m08:27:20
[2025-01-20T08:27:20.457+0000] {subprocess.py:106} INFO - [0m08:27:20  Done. PASS=0 WARN=0 ERROR=1 SKIP=0 TOTAL=1
[2025-01-20T08:27:22.572+0000] {subprocess.py:110} INFO - Command exited with return code 1
[2025-01-20T08:27:22.632+0000] {taskinstance.py:3311} ERROR - Task failed with exception
Traceback (most recent call last):
  File "/home/airflow/.local/lib/python3.12/site-packages/airflow/models/taskinstance.py", line 767, in _execute_task
    result = _execute_callable(context=context, **execute_callable_kwargs)
             ^^^^^^^^^^^^^^^^^^^^^^^^^^^^^^^^^^^^^^^^^^^^^^^^^^^^^^^^^^^^^
  File "/home/airflow/.local/lib/python3.12/site-packages/airflow/models/taskinstance.py", line 733, in _execute_callable
    return ExecutionCallableRunner(
           ^^^^^^^^^^^^^^^^^^^^^^^^
  File "/home/airflow/.local/lib/python3.12/site-packages/airflow/utils/operator_helpers.py", line 252, in run
    return self.func(*args, **kwargs)
           ^^^^^^^^^^^^^^^^^^^^^^^^^^
  File "/home/airflow/.local/lib/python3.12/site-packages/airflow/models/baseoperator.py", line 422, in wrapper
    return func(self, *args, **kwargs)
           ^^^^^^^^^^^^^^^^^^^^^^^^^^^
  File "/home/airflow/.local/lib/python3.12/site-packages/airflow/operators/bash.py", line 276, in execute
    raise AirflowException(
airflow.exceptions.AirflowException: Bash command failed. The command returned a non-zero exit code 1.
[2025-01-20T08:27:22.691+0000] {logging_mixin.py:190} INFO - Task instance in failure state
[2025-01-20T08:27:22.696+0000] {logging_mixin.py:190} INFO - Task start:2025-01-20 08:26:32.874416+00:00 end:2025-01-20 08:27:22.678340+00:00 duration:49.803924
[2025-01-20T08:27:22.699+0000] {logging_mixin.py:190} INFO - Task:<Task(BashOperator): run_dbt_transform> dag:<DAG: user_data_to_duckdb> dagrun:<DagRun user_data_to_duckdb @ 2025-01-20 08:08:50.334185+00:00: manual__2025-01-20T08:08:50.334185+00:00, state:running, queued_at: 2025-01-20 08:08:50.632127+00:00. externally triggered: True>
[2025-01-20T08:27:22.706+0000] {logging_mixin.py:190} INFO - Failure caused by Bash command failed. The command returned a non-zero exit code 1.
[2025-01-20T08:27:22.712+0000] {taskinstance.py:1225} INFO - Marking task as FAILED. dag_id=user_data_to_duckdb, task_id=run_dbt_transform, run_id=manual__2025-01-20T08:08:50.334185+00:00, execution_date=20250120T080850, start_date=20250120T082632, end_date=20250120T082722
[2025-01-20T08:27:22.817+0000] {taskinstance.py:340} INFO - ::group::Post task execution logs
[2025-01-20T08:27:22.828+0000] {standard_task_runner.py:124} ERROR - Failed to execute job 18 for task run_dbt_transform (Bash command failed. The command returned a non-zero exit code 1.; 485)
Traceback (most recent call last):
  File "/home/airflow/.local/lib/python3.12/site-packages/airflow/task/task_runner/standard_task_runner.py", line 117, in _start_by_fork
    ret = args.func(args, dag=self.dag)
          ^^^^^^^^^^^^^^^^^^^^^^^^^^^^^
  File "/home/airflow/.local/lib/python3.12/site-packages/airflow/cli/cli_config.py", line 49, in command
    return func(*args, **kwargs)
           ^^^^^^^^^^^^^^^^^^^^^
  File "/home/airflow/.local/lib/python3.12/site-packages/airflow/utils/cli.py", line 116, in wrapper
    return f(*args, **kwargs)
           ^^^^^^^^^^^^^^^^^^
  File "/home/airflow/.local/lib/python3.12/site-packages/airflow/cli/commands/task_command.py", line 483, in task_run
    task_return_code = _run_task_by_selected_method(args, _dag, ti)
                       ^^^^^^^^^^^^^^^^^^^^^^^^^^^^^^^^^^^^^^^^^^^^
  File "/home/airflow/.local/lib/python3.12/site-packages/airflow/cli/commands/task_command.py", line 256, in _run_task_by_selected_method
    return _run_raw_task(args, ti)
           ^^^^^^^^^^^^^^^^^^^^^^^
  File "/home/airflow/.local/lib/python3.12/site-packages/airflow/cli/commands/task_command.py", line 341, in _run_raw_task
    return ti._run_raw_task(
           ^^^^^^^^^^^^^^^^^
  File "/home/airflow/.local/lib/python3.12/site-packages/airflow/utils/session.py", line 97, in wrapper
    return func(*args, session=session, **kwargs)
           ^^^^^^^^^^^^^^^^^^^^^^^^^^^^^^^^^^^^^^
  File "/home/airflow/.local/lib/python3.12/site-packages/airflow/models/taskinstance.py", line 3005, in _run_raw_task
    return _run_raw_task(
           ^^^^^^^^^^^^^^
  File "/home/airflow/.local/lib/python3.12/site-packages/airflow/models/taskinstance.py", line 273, in _run_raw_task
    TaskInstance._execute_task_with_callbacks(
  File "/home/airflow/.local/lib/python3.12/site-packages/airflow/models/taskinstance.py", line 3159, in _execute_task_with_callbacks
    result = self._execute_task(context, task_orig)
             ^^^^^^^^^^^^^^^^^^^^^^^^^^^^^^^^^^^^^^
  File "/home/airflow/.local/lib/python3.12/site-packages/airflow/models/taskinstance.py", line 3183, in _execute_task
    return _execute_task(self, context, task_orig)
           ^^^^^^^^^^^^^^^^^^^^^^^^^^^^^^^^^^^^^^^
  File "/home/airflow/.local/lib/python3.12/site-packages/airflow/models/taskinstance.py", line 767, in _execute_task
    result = _execute_callable(context=context, **execute_callable_kwargs)
             ^^^^^^^^^^^^^^^^^^^^^^^^^^^^^^^^^^^^^^^^^^^^^^^^^^^^^^^^^^^^^
  File "/home/airflow/.local/lib/python3.12/site-packages/airflow/models/taskinstance.py", line 733, in _execute_callable
    return ExecutionCallableRunner(
           ^^^^^^^^^^^^^^^^^^^^^^^^
  File "/home/airflow/.local/lib/python3.12/site-packages/airflow/utils/operator_helpers.py", line 252, in run
    return self.func(*args, **kwargs)
           ^^^^^^^^^^^^^^^^^^^^^^^^^^
  File "/home/airflow/.local/lib/python3.12/site-packages/airflow/models/baseoperator.py", line 422, in wrapper
    return func(self, *args, **kwargs)
           ^^^^^^^^^^^^^^^^^^^^^^^^^^^
  File "/home/airflow/.local/lib/python3.12/site-packages/airflow/operators/bash.py", line 276, in execute
    raise AirflowException(
airflow.exceptions.AirflowException: Bash command failed. The command returned a non-zero exit code 1.
[2025-01-20T08:27:22.996+0000] {local_task_job_runner.py:266} INFO - Task exited with return code 1
[2025-01-20T08:27:23.064+0000] {taskinstance.py:3895} INFO - 0 downstream tasks scheduled from follow-on schedule check
[2025-01-20T08:27:23.081+0000] {local_task_job_runner.py:245} INFO - ::endgroup::
