[2025-01-20T08:40:44.599+0000] {local_task_job_runner.py:123} INFO - ::group::Pre task execution logs
[2025-01-20T08:40:44.954+0000] {taskinstance.py:2613} INFO - Dependencies all met for dep_context=non-requeueable deps ti=<TaskInstance: user_data_to_duckdb.run_dbt_transform manual__2025-01-20T08:28:43.659522+00:00 [queued]>
[2025-01-20T08:40:44.978+0000] {taskinstance.py:2613} INFO - Dependencies all met for dep_context=requeueable deps ti=<TaskInstance: user_data_to_duckdb.run_dbt_transform manual__2025-01-20T08:28:43.659522+00:00 [queued]>
[2025-01-20T08:40:44.980+0000] {taskinstance.py:2866} INFO - Starting attempt 3 of 4
[2025-01-20T08:40:45.029+0000] {taskinstance.py:2889} INFO - Executing <Task(BashOperator): run_dbt_transform> on 2025-01-20 08:28:43.659522+00:00
[2025-01-20T08:40:45.054+0000] {standard_task_runner.py:104} INFO - Running: ['***', 'tasks', 'run', 'user_data_to_duckdb', 'run_dbt_transform', 'manual__2025-01-20T08:28:43.659522+00:00', '--job-id', '26', '--raw', '--subdir', 'DAGS_FOLDER/api_duckdb_dag.py', '--cfg-path', '/tmp/tmpid5apuji']
[2025-01-20T08:40:45.058+0000] {standard_task_runner.py:105} INFO - Job 26: Subtask run_dbt_transform
[2025-01-20T08:40:45.056+0000] {warnings.py:112} WARNING - /home/***/.local/lib/python3.12/site-packages/***/task/task_runner/standard_task_runner.py:70: DeprecationWarning: This process (pid=737) is multi-threaded, use of fork() may lead to deadlocks in the child.
  pid = os.fork()

[2025-01-20T08:40:45.072+0000] {standard_task_runner.py:72} INFO - Started process 749 to run task
[2025-01-20T08:40:45.372+0000] {task_command.py:467} INFO - Running <TaskInstance: user_data_to_duckdb.run_dbt_transform manual__2025-01-20T08:28:43.659522+00:00 [running]> on host af5c9462b200
[2025-01-20T08:40:45.607+0000] {taskinstance.py:3132} INFO - Exporting env vars: AIRFLOW_CTX_DAG_OWNER='***' AIRFLOW_CTX_DAG_ID='user_data_to_duckdb' AIRFLOW_CTX_TASK_ID='run_dbt_transform' AIRFLOW_CTX_EXECUTION_DATE='2025-01-20T08:28:43.659522+00:00' AIRFLOW_CTX_TRY_NUMBER='3' AIRFLOW_CTX_DAG_RUN_ID='manual__2025-01-20T08:28:43.659522+00:00'
[2025-01-20T08:40:45.626+0000] {logging_mixin.py:190} INFO - Task instance is in running state
[2025-01-20T08:40:45.638+0000] {logging_mixin.py:190} INFO -  Previous state of the Task instance: queued
[2025-01-20T08:40:45.639+0000] {logging_mixin.py:190} INFO - Current task name:run_dbt_transform state:running start_date:2025-01-20 08:40:44.955899+00:00
[2025-01-20T08:40:45.640+0000] {logging_mixin.py:190} INFO - Dag name:user_data_to_duckdb and current dag run status:running
[2025-01-20T08:40:45.641+0000] {taskinstance.py:731} INFO - ::endgroup::
[2025-01-20T08:40:45.643+0000] {subprocess.py:78} INFO - Tmp dir root location: /tmp
[2025-01-20T08:40:45.653+0000] {subprocess.py:88} INFO - Running command: ['/usr/bin/bash', '-c', '\n        cd /opt/***/dags/dbt_models &&         dbt run --profiles-dir /opt/***/dbt/profiles.yml --target dev\n        ']
[2025-01-20T08:40:45.691+0000] {subprocess.py:99} INFO - Output:
[2025-01-20T08:40:54.129+0000] {subprocess.py:106} INFO - [0m08:40:54  Running with dbt=1.9.1
[2025-01-20T08:40:57.736+0000] {subprocess.py:106} INFO - [0m08:40:57  Registered adapter: duckdb=1.9.1
[2025-01-20T08:41:00.367+0000] {subprocess.py:106} INFO - [0m08:41:00  Found 1 model, 1 source, 424 macros
[2025-01-20T08:41:00.379+0000] {subprocess.py:106} INFO - [0m08:41:00
[2025-01-20T08:41:00.381+0000] {subprocess.py:106} INFO - [0m08:41:00  Concurrency: 1 threads (target='dev')
[2025-01-20T08:41:00.387+0000] {subprocess.py:106} INFO - [0m08:41:00
[2025-01-20T08:41:01.997+0000] {subprocess.py:106} INFO - [0m08:41:01  1 of 1 START sql table model main.transform_users .............................. [RUN]
[2025-01-20T08:41:02.383+0000] {subprocess.py:106} INFO - [0m08:41:02  1 of 1 ERROR creating sql table model main.transform_users ..................... [[31mERROR[0m in 0.37s]
[2025-01-20T08:41:02.448+0000] {subprocess.py:106} INFO - [0m08:41:02
[2025-01-20T08:41:02.451+0000] {subprocess.py:106} INFO - [0m08:41:02  Finished running 1 table model in 0 hours 0 minutes and 2.06 seconds (2.06s).
[2025-01-20T08:41:02.645+0000] {subprocess.py:106} INFO - [0m08:41:02
[2025-01-20T08:41:02.649+0000] {subprocess.py:106} INFO - [0m08:41:02  [31mCompleted with 1 error, 0 partial successes, and 0 warnings:[0m
[2025-01-20T08:41:02.651+0000] {subprocess.py:106} INFO - [0m08:41:02
[2025-01-20T08:41:02.654+0000] {subprocess.py:106} INFO - [0m08:41:02    Runtime Error in model transform_users (models/transform_users.sql)
[2025-01-20T08:41:02.656+0000] {subprocess.py:106} INFO -   Catalog Error: Table with name users does not exist!
[2025-01-20T08:41:02.660+0000] {subprocess.py:106} INFO -   Did you mean "my_duckdb_database.users"?
[2025-01-20T08:41:02.662+0000] {subprocess.py:106} INFO -   LINE 15:     SELECT * FROM "my_duckdb_database"."apidata"."users"
[2025-01-20T08:41:02.670+0000] {subprocess.py:106} INFO -                              ^
[2025-01-20T08:41:02.704+0000] {subprocess.py:106} INFO - [0m08:41:02
[2025-01-20T08:41:02.715+0000] {subprocess.py:106} INFO - [0m08:41:02  Done. PASS=0 WARN=0 ERROR=1 SKIP=0 TOTAL=1
[2025-01-20T08:41:04.873+0000] {subprocess.py:110} INFO - Command exited with return code 1
[2025-01-20T08:41:04.927+0000] {taskinstance.py:3311} ERROR - Task failed with exception
Traceback (most recent call last):
  File "/home/airflow/.local/lib/python3.12/site-packages/airflow/models/taskinstance.py", line 767, in _execute_task
    result = _execute_callable(context=context, **execute_callable_kwargs)
             ^^^^^^^^^^^^^^^^^^^^^^^^^^^^^^^^^^^^^^^^^^^^^^^^^^^^^^^^^^^^^
  File "/home/airflow/.local/lib/python3.12/site-packages/airflow/models/taskinstance.py", line 733, in _execute_callable
    return ExecutionCallableRunner(
           ^^^^^^^^^^^^^^^^^^^^^^^^
  File "/home/airflow/.local/lib/python3.12/site-packages/airflow/utils/operator_helpers.py", line 252, in run
    return self.func(*args, **kwargs)
           ^^^^^^^^^^^^^^^^^^^^^^^^^^
  File "/home/airflow/.local/lib/python3.12/site-packages/airflow/models/baseoperator.py", line 422, in wrapper
    return func(self, *args, **kwargs)
           ^^^^^^^^^^^^^^^^^^^^^^^^^^^
  File "/home/airflow/.local/lib/python3.12/site-packages/airflow/operators/bash.py", line 276, in execute
    raise AirflowException(
airflow.exceptions.AirflowException: Bash command failed. The command returned a non-zero exit code 1.
[2025-01-20T08:41:04.969+0000] {logging_mixin.py:190} INFO - Task instance in failure state
[2025-01-20T08:41:04.973+0000] {logging_mixin.py:190} INFO - Task start:2025-01-20 08:40:44.955899+00:00 end:2025-01-20 08:41:04.967896+00:00 duration:20.011997
[2025-01-20T08:41:04.977+0000] {logging_mixin.py:190} INFO - Task:<Task(BashOperator): run_dbt_transform> dag:<DAG: user_data_to_duckdb> dagrun:<DagRun user_data_to_duckdb @ 2025-01-20 08:28:43.659522+00:00: manual__2025-01-20T08:28:43.659522+00:00, state:running, queued_at: 2025-01-20 08:28:43.776172+00:00. externally triggered: True>
[2025-01-20T08:41:04.980+0000] {logging_mixin.py:190} INFO - Failure caused by Bash command failed. The command returned a non-zero exit code 1.
[2025-01-20T08:41:04.983+0000] {taskinstance.py:1225} INFO - Marking task as UP_FOR_RETRY. dag_id=user_data_to_duckdb, task_id=run_dbt_transform, run_id=manual__2025-01-20T08:28:43.659522+00:00, execution_date=20250120T082843, start_date=20250120T084044, end_date=20250120T084104
[2025-01-20T08:41:05.104+0000] {taskinstance.py:340} INFO - ::group::Post task execution logs
[2025-01-20T08:41:05.105+0000] {standard_task_runner.py:124} ERROR - Failed to execute job 26 for task run_dbt_transform (Bash command failed. The command returned a non-zero exit code 1.; 749)
Traceback (most recent call last):
  File "/home/airflow/.local/lib/python3.12/site-packages/airflow/task/task_runner/standard_task_runner.py", line 117, in _start_by_fork
    ret = args.func(args, dag=self.dag)
          ^^^^^^^^^^^^^^^^^^^^^^^^^^^^^
  File "/home/airflow/.local/lib/python3.12/site-packages/airflow/cli/cli_config.py", line 49, in command
    return func(*args, **kwargs)
           ^^^^^^^^^^^^^^^^^^^^^
  File "/home/airflow/.local/lib/python3.12/site-packages/airflow/utils/cli.py", line 116, in wrapper
    return f(*args, **kwargs)
           ^^^^^^^^^^^^^^^^^^
  File "/home/airflow/.local/lib/python3.12/site-packages/airflow/cli/commands/task_command.py", line 483, in task_run
    task_return_code = _run_task_by_selected_method(args, _dag, ti)
                       ^^^^^^^^^^^^^^^^^^^^^^^^^^^^^^^^^^^^^^^^^^^^
  File "/home/airflow/.local/lib/python3.12/site-packages/airflow/cli/commands/task_command.py", line 256, in _run_task_by_selected_method
    return _run_raw_task(args, ti)
           ^^^^^^^^^^^^^^^^^^^^^^^
  File "/home/airflow/.local/lib/python3.12/site-packages/airflow/cli/commands/task_command.py", line 341, in _run_raw_task
    return ti._run_raw_task(
           ^^^^^^^^^^^^^^^^^
  File "/home/airflow/.local/lib/python3.12/site-packages/airflow/utils/session.py", line 97, in wrapper
    return func(*args, session=session, **kwargs)
           ^^^^^^^^^^^^^^^^^^^^^^^^^^^^^^^^^^^^^^
  File "/home/airflow/.local/lib/python3.12/site-packages/airflow/models/taskinstance.py", line 3005, in _run_raw_task
    return _run_raw_task(
           ^^^^^^^^^^^^^^
  File "/home/airflow/.local/lib/python3.12/site-packages/airflow/models/taskinstance.py", line 273, in _run_raw_task
    TaskInstance._execute_task_with_callbacks(
  File "/home/airflow/.local/lib/python3.12/site-packages/airflow/models/taskinstance.py", line 3159, in _execute_task_with_callbacks
    result = self._execute_task(context, task_orig)
             ^^^^^^^^^^^^^^^^^^^^^^^^^^^^^^^^^^^^^^
  File "/home/airflow/.local/lib/python3.12/site-packages/airflow/models/taskinstance.py", line 3183, in _execute_task
    return _execute_task(self, context, task_orig)
           ^^^^^^^^^^^^^^^^^^^^^^^^^^^^^^^^^^^^^^^
  File "/home/airflow/.local/lib/python3.12/site-packages/airflow/models/taskinstance.py", line 767, in _execute_task
    result = _execute_callable(context=context, **execute_callable_kwargs)
             ^^^^^^^^^^^^^^^^^^^^^^^^^^^^^^^^^^^^^^^^^^^^^^^^^^^^^^^^^^^^^
  File "/home/airflow/.local/lib/python3.12/site-packages/airflow/models/taskinstance.py", line 733, in _execute_callable
    return ExecutionCallableRunner(
           ^^^^^^^^^^^^^^^^^^^^^^^^
  File "/home/airflow/.local/lib/python3.12/site-packages/airflow/utils/operator_helpers.py", line 252, in run
    return self.func(*args, **kwargs)
           ^^^^^^^^^^^^^^^^^^^^^^^^^^
  File "/home/airflow/.local/lib/python3.12/site-packages/airflow/models/baseoperator.py", line 422, in wrapper
    return func(self, *args, **kwargs)
           ^^^^^^^^^^^^^^^^^^^^^^^^^^^
  File "/home/airflow/.local/lib/python3.12/site-packages/airflow/operators/bash.py", line 276, in execute
    raise AirflowException(
airflow.exceptions.AirflowException: Bash command failed. The command returned a non-zero exit code 1.
[2025-01-20T08:41:05.261+0000] {local_task_job_runner.py:266} INFO - Task exited with return code 1
[2025-01-20T08:41:05.343+0000] {taskinstance.py:3895} INFO - 0 downstream tasks scheduled from follow-on schedule check
[2025-01-20T08:41:05.366+0000] {local_task_job_runner.py:245} INFO - ::endgroup::
