[2025-01-20T07:35:33.338+0000] {local_task_job_runner.py:123} INFO - ::group::Pre task execution logs
[2025-01-20T07:35:33.376+0000] {taskinstance.py:2613} INFO - Dependencies all met for dep_context=non-requeueable deps ti=<TaskInstance: user_data_to_duckdb.run_dbt_transform manual__2025-01-20T07:32:30.772773+00:00 [queued]>
[2025-01-20T07:35:33.404+0000] {taskinstance.py:2613} INFO - Dependencies all met for dep_context=requeueable deps ti=<TaskInstance: user_data_to_duckdb.run_dbt_transform manual__2025-01-20T07:32:30.772773+00:00 [queued]>
[2025-01-20T07:35:33.407+0000] {taskinstance.py:2866} INFO - Starting attempt 2 of 3
[2025-01-20T07:35:33.444+0000] {taskinstance.py:2889} INFO - Executing <Task(BashOperator): run_dbt_transform> on 2025-01-20 07:32:30.772773+00:00
[2025-01-20T07:35:33.459+0000] {warnings.py:112} WARNING - /home/***/.local/lib/python3.12/site-packages/***/task/task_runner/standard_task_runner.py:70: DeprecationWarning: This process (pid=682) is multi-threaded, use of fork() may lead to deadlocks in the child.
  pid = os.fork()

[2025-01-20T07:35:33.463+0000] {standard_task_runner.py:72} INFO - Started process 687 to run task
[2025-01-20T07:35:33.464+0000] {standard_task_runner.py:104} INFO - Running: ['***', 'tasks', 'run', 'user_data_to_duckdb', 'run_dbt_transform', 'manual__2025-01-20T07:32:30.772773+00:00', '--job-id', '21', '--raw', '--subdir', 'DAGS_FOLDER/api_duckdb_dag.py', '--cfg-path', '/tmp/tmp2ouh4826']
[2025-01-20T07:35:33.469+0000] {standard_task_runner.py:105} INFO - Job 21: Subtask run_dbt_transform
[2025-01-20T07:35:33.557+0000] {task_command.py:467} INFO - Running <TaskInstance: user_data_to_duckdb.run_dbt_transform manual__2025-01-20T07:32:30.772773+00:00 [running]> on host f1a6bf7b32bb
[2025-01-20T07:35:34.117+0000] {taskinstance.py:3132} INFO - Exporting env vars: AIRFLOW_CTX_DAG_OWNER='***' AIRFLOW_CTX_DAG_ID='user_data_to_duckdb' AIRFLOW_CTX_TASK_ID='run_dbt_transform' AIRFLOW_CTX_EXECUTION_DATE='2025-01-20T07:32:30.772773+00:00' AIRFLOW_CTX_TRY_NUMBER='2' AIRFLOW_CTX_DAG_RUN_ID='manual__2025-01-20T07:32:30.772773+00:00'
[2025-01-20T07:35:34.120+0000] {logging_mixin.py:190} INFO - Task instance is in running state
[2025-01-20T07:35:34.121+0000] {logging_mixin.py:190} INFO -  Previous state of the Task instance: queued
[2025-01-20T07:35:34.122+0000] {logging_mixin.py:190} INFO - Current task name:run_dbt_transform state:running start_date:2025-01-20 07:35:33.378284+00:00
[2025-01-20T07:35:34.122+0000] {logging_mixin.py:190} INFO - Dag name:user_data_to_duckdb and current dag run status:running
[2025-01-20T07:35:34.123+0000] {taskinstance.py:731} INFO - ::endgroup::
[2025-01-20T07:35:34.139+0000] {subprocess.py:78} INFO - Tmp dir root location: /tmp
[2025-01-20T07:35:34.141+0000] {subprocess.py:88} INFO - Running command: ['/usr/bin/bash', '-c', '\n        cd /opt/***/dags/dbt_models &&         dbt run --profiles-dir /opt/***/dbt/profiles.yml --target dev\n        ']
[2025-01-20T07:35:34.174+0000] {subprocess.py:99} INFO - Output:
[2025-01-20T07:35:50.214+0000] {subprocess.py:106} INFO - [0m07:35:50  Running with dbt=1.9.1
[2025-01-20T07:35:54.320+0000] {subprocess.py:106} INFO - [0m07:35:54  Registered adapter: duckdb=1.9.1
[2025-01-20T07:36:22.572+0000] {subprocess.py:106} INFO - [0m07:36:22  Unable to do partial parsing because a project config has changed
[2025-01-20T07:36:25.734+0000] {job.py:229} INFO - Heartbeat recovered after 37.03 seconds
[2025-01-20T07:36:32.082+0000] {subprocess.py:106} INFO - [0m07:36:32  Encountered an error:
[2025-01-20T07:36:32.085+0000] {subprocess.py:106} INFO - Compilation Error
[2025-01-20T07:36:32.088+0000] {subprocess.py:106} INFO -   Model 'model.my_dbt_project.transform_users' (models/transform_users.sql) depends on a source named 'my_dbt_profile.users' which was not found
[2025-01-20T07:36:36.059+0000] {subprocess.py:110} INFO - Command exited with return code 2
[2025-01-20T07:36:37.088+0000] {taskinstance.py:3311} ERROR - Task failed with exception
Traceback (most recent call last):
  File "/home/airflow/.local/lib/python3.12/site-packages/airflow/models/taskinstance.py", line 767, in _execute_task
    result = _execute_callable(context=context, **execute_callable_kwargs)
             ^^^^^^^^^^^^^^^^^^^^^^^^^^^^^^^^^^^^^^^^^^^^^^^^^^^^^^^^^^^^^
  File "/home/airflow/.local/lib/python3.12/site-packages/airflow/models/taskinstance.py", line 733, in _execute_callable
    return ExecutionCallableRunner(
           ^^^^^^^^^^^^^^^^^^^^^^^^
  File "/home/airflow/.local/lib/python3.12/site-packages/airflow/utils/operator_helpers.py", line 252, in run
    return self.func(*args, **kwargs)
           ^^^^^^^^^^^^^^^^^^^^^^^^^^
  File "/home/airflow/.local/lib/python3.12/site-packages/airflow/models/baseoperator.py", line 422, in wrapper
    return func(self, *args, **kwargs)
           ^^^^^^^^^^^^^^^^^^^^^^^^^^^
  File "/home/airflow/.local/lib/python3.12/site-packages/airflow/operators/bash.py", line 276, in execute
    raise AirflowException(
airflow.exceptions.AirflowException: Bash command failed. The command returned a non-zero exit code 2.
[2025-01-20T07:36:37.177+0000] {logging_mixin.py:190} INFO - Task instance in failure state
[2025-01-20T07:36:37.179+0000] {logging_mixin.py:190} INFO - Task start:2025-01-20 07:35:33.378284+00:00 end:2025-01-20 07:36:37.175217+00:00 duration:63.796933
[2025-01-20T07:36:37.181+0000] {logging_mixin.py:190} INFO - Task:<Task(BashOperator): run_dbt_transform> dag:<DAG: user_data_to_duckdb> dagrun:<DagRun user_data_to_duckdb @ 2025-01-20 07:32:30.772773+00:00: manual__2025-01-20T07:32:30.772773+00:00, state:running, queued_at: 2025-01-20 07:32:30.908313+00:00. externally triggered: True>
[2025-01-20T07:36:37.192+0000] {logging_mixin.py:190} INFO - Failure caused by Bash command failed. The command returned a non-zero exit code 2.
[2025-01-20T07:36:37.195+0000] {taskinstance.py:1225} INFO - Marking task as UP_FOR_RETRY. dag_id=user_data_to_duckdb, task_id=run_dbt_transform, run_id=manual__2025-01-20T07:32:30.772773+00:00, execution_date=20250120T073230, start_date=20250120T073533, end_date=20250120T073637
[2025-01-20T07:36:37.292+0000] {taskinstance.py:340} INFO - ::group::Post task execution logs
[2025-01-20T07:36:37.296+0000] {standard_task_runner.py:124} ERROR - Failed to execute job 21 for task run_dbt_transform (Bash command failed. The command returned a non-zero exit code 2.; 687)
Traceback (most recent call last):
  File "/home/airflow/.local/lib/python3.12/site-packages/airflow/task/task_runner/standard_task_runner.py", line 117, in _start_by_fork
    ret = args.func(args, dag=self.dag)
          ^^^^^^^^^^^^^^^^^^^^^^^^^^^^^
  File "/home/airflow/.local/lib/python3.12/site-packages/airflow/cli/cli_config.py", line 49, in command
    return func(*args, **kwargs)
           ^^^^^^^^^^^^^^^^^^^^^
  File "/home/airflow/.local/lib/python3.12/site-packages/airflow/utils/cli.py", line 116, in wrapper
    return f(*args, **kwargs)
           ^^^^^^^^^^^^^^^^^^
  File "/home/airflow/.local/lib/python3.12/site-packages/airflow/cli/commands/task_command.py", line 483, in task_run
    task_return_code = _run_task_by_selected_method(args, _dag, ti)
                       ^^^^^^^^^^^^^^^^^^^^^^^^^^^^^^^^^^^^^^^^^^^^
  File "/home/airflow/.local/lib/python3.12/site-packages/airflow/cli/commands/task_command.py", line 256, in _run_task_by_selected_method
    return _run_raw_task(args, ti)
           ^^^^^^^^^^^^^^^^^^^^^^^
  File "/home/airflow/.local/lib/python3.12/site-packages/airflow/cli/commands/task_command.py", line 341, in _run_raw_task
    return ti._run_raw_task(
           ^^^^^^^^^^^^^^^^^
  File "/home/airflow/.local/lib/python3.12/site-packages/airflow/utils/session.py", line 97, in wrapper
    return func(*args, session=session, **kwargs)
           ^^^^^^^^^^^^^^^^^^^^^^^^^^^^^^^^^^^^^^
  File "/home/airflow/.local/lib/python3.12/site-packages/airflow/models/taskinstance.py", line 3005, in _run_raw_task
    return _run_raw_task(
           ^^^^^^^^^^^^^^
  File "/home/airflow/.local/lib/python3.12/site-packages/airflow/models/taskinstance.py", line 273, in _run_raw_task
    TaskInstance._execute_task_with_callbacks(
  File "/home/airflow/.local/lib/python3.12/site-packages/airflow/models/taskinstance.py", line 3159, in _execute_task_with_callbacks
    result = self._execute_task(context, task_orig)
             ^^^^^^^^^^^^^^^^^^^^^^^^^^^^^^^^^^^^^^
  File "/home/airflow/.local/lib/python3.12/site-packages/airflow/models/taskinstance.py", line 3183, in _execute_task
    return _execute_task(self, context, task_orig)
           ^^^^^^^^^^^^^^^^^^^^^^^^^^^^^^^^^^^^^^^
  File "/home/airflow/.local/lib/python3.12/site-packages/airflow/models/taskinstance.py", line 767, in _execute_task
    result = _execute_callable(context=context, **execute_callable_kwargs)
             ^^^^^^^^^^^^^^^^^^^^^^^^^^^^^^^^^^^^^^^^^^^^^^^^^^^^^^^^^^^^^
  File "/home/airflow/.local/lib/python3.12/site-packages/airflow/models/taskinstance.py", line 733, in _execute_callable
    return ExecutionCallableRunner(
           ^^^^^^^^^^^^^^^^^^^^^^^^
  File "/home/airflow/.local/lib/python3.12/site-packages/airflow/utils/operator_helpers.py", line 252, in run
    return self.func(*args, **kwargs)
           ^^^^^^^^^^^^^^^^^^^^^^^^^^
  File "/home/airflow/.local/lib/python3.12/site-packages/airflow/models/baseoperator.py", line 422, in wrapper
    return func(self, *args, **kwargs)
           ^^^^^^^^^^^^^^^^^^^^^^^^^^^
  File "/home/airflow/.local/lib/python3.12/site-packages/airflow/operators/bash.py", line 276, in execute
    raise AirflowException(
airflow.exceptions.AirflowException: Bash command failed. The command returned a non-zero exit code 2.
[2025-01-20T07:36:37.497+0000] {local_task_job_runner.py:266} INFO - Task exited with return code 1
[2025-01-20T07:36:38.262+0000] {taskinstance.py:3895} INFO - 0 downstream tasks scheduled from follow-on schedule check
[2025-01-20T07:36:38.270+0000] {local_task_job_runner.py:245} INFO - ::endgroup::
